examples/deep_script.txt
add 1 S 445426 41
add 2 S 598350 83
add 3 B 402070 61
add 4 B 482790 79
add 5 B 587591 10
add 6 B 475337 64
add 7 S 562416 83
add 8 S 473292 53
add 9 S 561671 27
add 10 S 454059 42
add 11 B 564126 75
cancel 10
add 12 S 593504 16
add 13 S 488421 13
add 14 B 465954 10
add 15 S 512016 92
cancel 14
add 16 B 519233 11
cancel 12
cancel 7
add 17 S 507232 97
add 18 S 579870 28
add 19 B 552247 15
cancel 15
add 20 B 539305 91
cancel 3
add 21 S 454693 9
add 22 S 546121 10
add 23 S 597630 84
cancel 1
add 24 B 494700 87
add 25 S 599431 40
add 26 S 589447 46
cancel 8
add 27 B 448901 78
add 28 B 403935 47
add 29 S 590114 65
add 30 S 428889 64
add 31 B 490643 22
add 32 S 433915 21
add 33 B 530804 77
add 34 B 565882 73
add 35 S 559047 76
add 36 B 580171 15
add 37 S 437858 2
add 38 B 492751 86
add 39 B 421514 3
add 40 B 560131 39
add 41 S 589469 65
add 42 S 412919 90
add 43 B 493004 57
add 44 B 494157 83
add 45 B 561925 30
cancel 6
add 46 S 434256 78
add 47 B 431690 37
add 48 B 461319 3
cancel 35
add 49 S 473019 22
add 50 B 482676 11
add 51 S 459899 63
add 52 B 508949 92
add 53 B 536017 98
add 54 B 462060 64
add 55 B 583336 80
add 56 S 597328 30
add 57 S 453698 59
add 58 B 421658 80
add 59 S 463286 59
add 60 B 463009 4
cancel 50
add 61 S 469428 22
add 62 B 578661 49
add 63 S 410067 99
cancel 28
add 64 S 585106 15
add 65 B 567780 15
add 66 S 585489 12
add 67 B 446400 60
add 68 S 493981 92
add 69 S 505885 75
add 70 S 422613 66
add 71 S 429466 78
cancel 67
cancel 47
add 72 S 595565 97
cancel 55
add 73 B 486113 63
add 74 B 554721 43
add 75 B 434231 46
add 76 S 540966 40
cancel 68
add 77 B 584434 36
cancel 69
add 78 S 453438 36
add 79 B 575961 7
add 80 B 475198 60
add 81 B 467873 43
add 82 B 554695 48
add 83 S 464178 28
add 84 B 572780 55
add 85 B 408542 84
add 86 B 521297 77
add 87 S 572991 99
add 88 S 411012 95
cancel 74
add 89 B 542743 47
add 90 S 423249 77
add 91 S 429733 95
add 92 B 420236 70
cancel 38
add 93 B 534545 43
cancel 21
cancel 41
cancel 57
add 94 B 512924 77
add 95 S 571959 40
add 96 B 581568 91
add 97 B 548449 50
add 98 B 479387 25
add 99 B 473434 28
add 100 B 501472 86
cancel 62
add 101 S 456803 9
add 102 B 510339 77
add 103 B 488331 48
add 104 S 535782 23
cancel 71
add 105 B 433304 60
add 106 S 503664 84
cancel 98
add 107 S 473673 22
add 108 S 479668 31
add 109 S 559780 55
add 110 S 475350 28
add 111 B 585537 35
cancel 94
add 112 B 442927 54
add 113 S 488923 53
add 114 S 521707 11
cancel 49
add 115 B 530851 31
cancel 72
cancel 80
add 116 B 428261 89
add 117 S 551943 27
add 118 S 407841 46
add 119 S 560821 83
cancel 16
add 120 S 576662 92
add 121 S 477578 4
cancel 96
add 122 B 548910 32
add 123 B 411913 31
add 124 B 566141 11
add 125 B 401450 86
add 126 S 409734 53
add 127 S 446422 75
add 128 B 578088 95
add 129 B 430584 72
add 130 B 492140 83
add 131 B 464852 42
add 132 S 508394 11
add 133 S 496346 41
add 134 S 480873 51
add 135 B 495309 68
add 136 B 461371 58
add 137 B 556388 77
cancel 5
add 138 S 532433 22
add 139 B 455816 51
add 140 S 466750 36
add 141 S 470172 28
add 142 B 512346 69
add 143 S 510069 94
add 144 B 546185 28
add 145 S 421102 82
cancel 42
add 146 B 593610 85
add 147 B 517893 67
add 148 S 569300 94
cancel 22
add 149 B 548912 58
add 150 B 510207 63
add 151 S 457154 99
add 152 B 505751 79
add 153 B 534519 19
add 154 B 465460 31
add 155 B 471120 78
add 156 B 436289 43
add 157 S 589118 33
add 158 B 532428 64
add 159 S 458296 7
add 160 S 545492 65
add 161 S 520851 31
add 162 S 431521 35
add 163 S 442646 51
add 164 B 572845 85
add 165 S 575075 51
add 166 B 583628 2
add 167 S 490073 29
add 168 B 506972 55
add 169 B 590850 43
add 170 S 402255 72
add 171 S 551801 9
cancel 54
cancel 138
add 172 B 464005 100
add 173 B 596294 86
add 174 S 487887 40
add 175 S 418337 61
add 176 B 547024 34
add 177 S 569152 57
add 178 B 461375 69
add 179 B 479901 49
add 180 S 424436 6
add 181 B 580130 8
add 182 S 437238 48
add 183 S 467636 89
add 184 B 486606 31
cancel 59
add 185 B 487416 2
add 186 B 557244 76
add 187 B 473490 2
add 188 B 489718 22
add 189 B 469426 26
add 190 S 475866 89
cancel 167
add 191 S 443928 75
add 192 B 599235 96
add 193 B 519022 70
add 194 B 421032 18
add 195 B 437299 56
add 196 S 505656 87
add 197 S 404047 92
add 198 S 568261 52
cancel 76
add 199 B 475818 41
add 200 B 558629 73
add 201 B 549587 75
add 202 B 476638 29
cancel 36
add 203 S 405748 46
add 204 B 575194 86
cancel 23
add 205 B 416473 70
add 206 S 427506 41
add 207 B 585753 60
cancel 4
add 208 S 576350 57
add 209 B 574121 65
add 210 B 429344 92
cancel 113
add 211 S 448439 14
add 212 S 474372 64
add 213 S 536997 51
add 214 S 476825 73
add 215 S 463719 59
add 216 B 474242 54
add 217 B 510903 30
add 218 B 507470 5
cancel 73
add 219 B 564780 36
add 220 B 471675 76
cancel 111
add 221 S 536989 23
add 222 B 533677 47
add 223 B 411184 69
add 224 B 554103 44
add 225 S 449358 86
add 226 S 496389 82
add 227 B 525354 80
add 228 B 580662 66
cancel 2
add 229 B 552297 41
add 230 S 489662 83
cancel 184
add 231 S 403856 54
add 232 S 541701 20
cancel 183
add 233 S 422770 15
add 234 S 489545 49
add 235 B 586060 10
add 236 S 400700 78
cancel 99
add 237 B 549240 50
add 238 S 416703 20
add 239 B 544949 7
add 240 S 560810 99
add 241 B 416882 18
add 242 B 540849 41
cancel 197
add 243 S 420157 97
add 244 B 497773 24
add 245 B 571661 78
cancel 200
add 246 S 410316 1
add 247 B 536245 40
add 248 B 576495 92
add 249 S 529366 64
add 250 S 410765 87
add 251 B 428053 12
cancel 194
cancel 86
add 252 B 443111 73
add 253 B 419355 40
add 254 S 403880 51
add 255 B 561188 26
cancel 190
add 256 B 505400 57
add 257 S 511106 33
add 258 B 574347 86
add 259 S 574611 69
add 260 B 524206 74
add 261 B 471947 12
add 262 B 401794 15
add 263 B 562295 14
add 264 B 440866 5
add 265 S 485296 86
add 266 B 430039 93
add 267 B 592809 81
add 268 S 562231 63
add 269 B 419537 96
add 270 B 569964 34
add 271 S 431325 67
add 272 S 561860 70
add 273 S 520386 17
cancel 206
add 274 S 583901 93
add 275 S 594215 48
cancel 264
add 276 S 489573 62
add 277 S 490945 20
add 278 S 483773 3
add 279 B 509114 58
add 280 B 452311 30
add 281 B 505105 33
add 282 S 515934 92
add 283 S 598871 26
add 284 S 446058 80
add 285 S 415546 7
add 286 B 446604 20
add 287 S 549848 44
add 288 B 479805 79
add 289 B 553180 91
add 290 B 493774 86
add 291 S 567713 48
add 292 S 422769 53
add 293 B 425839 23
add 294 B 468215 51
add 295 S 471677 83
add 296 B 449703 2
add 297 S 465803 31
add 298 B 457042 31
cancel 97
add 299 S 427700 99
add 300 B 470683 4
add 301 S 485766 65
add 302 B 526320 29
add 303 B 546815 97
cancel 112
cancel 185
cancel 93
add 304 S 519398 97
add 305 B 502876 52
add 306 B 512003 4
add 307 B 440104 90
add 308 B 471284 49
add 309 S 569909 86
add 310 B 423636 69
cancel 207
add 311 S 441049 86
add 312 B 527620 10
add 313 B 567158 58
add 314 B 568625 98
add 315 B 503696 12
add 316 S 444330 78
add 317 S 533173 60
add 318 B 432957 22
add 319 B 531257 55
add 320 S 414482 60
add 321 B 537791 89
add 322 B 520184 48
add 323 S 562873 35
add 324 S 579677 81
add 325 S 421354 83
add 326 S 469592 77
add 327 S 425963 10
add 328 S 470561 32
add 329 S 493350 42
add 330 S 565438 65
add 331 B 477172 31
cancel 83
add 332 S 573622 43
cancel 188
add 333 S 493664 13
cancel 258
add 334 S 472779 45
add 335 B 548041 94
add 336 B 501080 39
cancel 63
cancel 208
add 337 B 498670 10
add 338 S 418563 7
cancel 33
add 339 S 461812 81
add 340 S 423662 5
add 341 B 430623 71
cancel 52
cancel 169
add 342 S 547334 49
add 343 B 568909 96
add 344 S 598902 19
add 345 S 584066 42
add 346 B 487757 29
add 347 S 561261 93
add 348 S 467435 97
add 349 S 427804 98
add 350 S 567076 59
add 351 B 505531 22
add 352 S 535259 52
add 353 B 408603 86
add 354 B 494535 72
add 355 B 512708 66
add 356 B 485153 66
add 357 S 444884 73
add 358 B 562288 37
cancel 281
add 359 S 462308 70
add 360 B 413938 32
add 361 B 512900 50
add 362 B 516626 80
add 363 B 513318 31
add 364 B 450219 59
add 365 B 436336 86
add 366 B 420243 19
add 367 S 557737 5
cancel 295
add 368 S 595637 68
add 369 B 451721 35
add 370 S 509033 93
add 371 B 469083 16
