examples/dense_script.txt
add 1 S 499980 88
add 2 B 500010 96
add 3 B 499969 65
cancel 1
add 4 B 500039 5
add 5 S 500019 55
cancel 4
cancel 5
add 6 S 500015 67
add 7 S 500015 15
add 8 S 500031 53
add 9 S 500022 32
add 10 S 499950 13
add 11 S 500009 48
add 12 S 500044 53
add 13 S 500012 35
cancel 3
add 14 S 499979 50
add 15 S 499958 43
cancel 6
add 16 S 499966 55
add 17 S 499952 39
add 18 S 500034 72
add 19 B 499960 5
add 20 S 500012 65
add 21 B 500044 12
add 22 B 499955 69
add 23 S 500038 18
cancel 2
add 24 S 499954 55
add 25 B 500000 48
cancel 20
add 26 S 499985 39
add 27 B 500006 25
add 28 S 499998 13
add 29 B 499970 69
add 30 B 499993 43
cancel 7
cancel 11
cancel 28
add 31 S 499989 94
add 32 S 499991 38
add 33 S 499974 65
add 34 S 499988 27
add 35 S 499954 50
add 36 B 500022 23
add 37 S 499950 95
cancel 37
add 38 S 499962 35
cancel 32
add 39 S 499992 64
add 40 B 499950 39
add 41 S 500034 41
add 42 B 500021 29
add 43 S 499997 29
add 44 S 500041 78
add 45 S 499998 78
cancel 26
add 46 S 499989 99
add 47 S 500005 12
cancel 41
add 48 S 499999 86
add 49 S 500015 89
add 50 B 499992 52
cancel 15
add 51 B 499984 50
cancel 33
add 52 B 499973 14
cancel 47
add 53 B 499964 79
cancel 51
add 54 B 500040 43
add 55 B 500046 1
cancel 22
add 56 S 500026 20
add 57 B 499952 58
add 58 B 499976 18
add 59 S 499980 26
cancel 29
add 60 B 499983 42
add 61 B 500009 69
add 62 B 499998 32
add 63 B 500043 4
add 64 S 500043 13
cancel 50
cancel 9
add 65 S 500040 14
add 66 S 499975 30
cancel 36
add 67 S 499979 96
cancel 23
add 68 B 500030 2
add 69 B 500016 69
add 70 B 499958 39
add 71 B 500008 99
cancel 35
add 72 B 500026 32
add 73 B 500018 70
cancel 43
add 74 S 500044 98
add 75 S 499961 72
add 76 S 500030 77
add 77 S 500048 36
add 78 S 499964 19
add 79 B 500008 38
cancel 16
add 80 B 500049 34
add 81 S 500023 98
add 82 S 500028 44
cancel 45
cancel 24
cancel 74
add 83 S 499982 23
add 84 S 499963 38
cancel 66
add 85 S 500041 89
add 86 B 499963 23
cancel 81
add 87 S 499955 87
add 88 B 500028 88
add 89 B 499991 39
add 90 S 499954 3
add 91 B 500034 36
add 92 S 499993 14
add 93 B 499959 31
add 94 S 499961 9
add 95 S 499973 18
cancel 63
add 96 B 500035 55
add 97 B 500007 14
add 98 S 499952 34
cancel 62
add 99 B 499995 34
add 100 B 500046 79
add 101 B 500032 79
cancel 65
add 102 B 500003 93
add 103 B 500032 96
add 104 S 500002 84
add 105 B 500042 67
add 106 S 499960 3
cancel 69
add 107 B 499960 37
add 108 B 500012 71
add 109 B 500016 7
cancel 54
add 110 S 499959 46
add 111 S 500001 90
add 112 S 500003 22
add 113 S 499961 4
add 114 S 499972 42
add 115 S 500007 18
add 116 S 499953 38
add 117 S 500014 41
add 118 S 500002 64
cancel 18
add 119 S 500030 87
add 120 S 500002 64
add 121 S 499950 61
add 122 B 500024 76
add 123 B 500015 63
add 124 B 500011 13
add 125 S 500041 13
cancel 61
add 126 S 500036 41
add 127 B 500006 81
add 128 S 500032 33
cancel 95
add 129 B 500020 78
add 130 S 499971 54
add 131 B 499995 2
add 132 S 500017 44
add 133 B 500040 100
add 134 S 500041 89
cancel 82
add 135 B 500036 63
add 136 S 500045 78
add 137 S 499955 10
add 138 S 500020 72
add 139 B 499991 83
add 140 S 500033 66
add 141 B 499986 79
add 142 B 499950 16
add 143 S 500029 9
add 144 S 500021 74
add 145 B 500042 18
add 146 B 499991 57
cancel 83
add 147 S 500024 73
add 148 S 499991 72
add 149 S 499991 5
add 150 B 500040 45
add 151 S 500044 70
add 152 S 499978 68
add 153 S 500019 10
add 154 B 500002 42
add 155 S 499999 66
add 156 S 499996 16
add 157 B 500012 87
add 158 S 500025 38
add 159 B 500009 4
add 160 S 500020 43
add 161 S 499961 15
add 162 S 499963 86
add 163 S 499952 41
add 164 S 500004 95
cancel 130
add 165 B 500000 14
add 166 S 500050 30
add 167 S 500050 34
add 168 S 499963 87
add 169 S 499982 97
add 170 S 500014 87
add 171 B 500028 94
add 172 S 500000 16
add 173 B 499990 13
cancel 73
add 174 B 500005 86
add 175 B 499991 55
add 176 B 500010 28
add 177 B 499994 54
add 178 B 499978 84
cancel 177
add 179 B 500016 96
add 180 S 499996 49
add 181 S 499979 69
add 182 S 499983 74
add 183 B 500019 64
add 184 B 500009 86
add 185 B 500026 24
add 186 S 499958 90
add 187 S 499981 93
add 188 S 499985 73
add 189 S 500049 27
add 190 B 500011 70
add 191 B 500036 25
add 192 S 500046 31
add 193 B 499997 91
add 194 S 499979 26
add 195 B 499959 41
add 196 S 500006 62
add 197 B 499958 41
cancel 158
add 198 S 500047 94
add 199 S 499992 23
add 200 S 499963 23
add 201 B 500048 68
add 202 S 499971 46
add 203 S 500014 17
add 204 S 499959 89
cancel 8
cancel 38
add 205 S 500001 91
add 206 B 499983 85
add 207 B 499979 55
add 208 S 500043 49
cancel 79
add 209 S 499997 18
add 210 S 500043 37
add 211 S 499991 93
add 212 B 500009 90
add 213 S 499992 21
add 214 S 500011 84
add 215 B 499982 28
add 216 B 500017 96
add 217 S 500021 72
add 218 S 500040 82
add 219 S 499978 22
add 220 S 500011 34
add 221 B 499993 5
add 222 B 500042 43
cancel 145
add 223 B 500035 29
add 224 S 499987 81
add 225 S 500043 2
add 226 B 500006 7
add 227 B 499995 61
add 228 B 500030 31
cancel 183
add 229 S 499976 8
add 230 B 500050 42
add 231 S 500006 14
add 232 B 499967 37
add 233 S 499997 25
add 234 S 500047 6
add 235 B 499998 66
add 236 S 499988 11
add 237 B 499983 76
add 238 B 499965 98
add 239 B 499966 1
add 240 B 500021 98
add 241 B 499999 59
add 242 B 499980 19
add 243 S 500042 37
add 244 S 499994 12
add 245 S 500040 79
cancel 175
add 246 B 500003 84
add 247 B 499956 96
add 248 S 499981 63
add 249 B 499958 96
add 250 B 499984 14
add 251 B 500048 52
add 252 B 500031 29
add 253 S 500043 69
add 254 S 499963 33
add 255 S 499957 30
cancel 214
add 256 B 499983 29
add 257 B 500023 13
add 258 S 499980 5
add 259 S 499962 69
add 260 B 499996 50
cancel 135
add 261 S 500003 19
add 262 B 499963 35
add 263 S 500045 91
add 264 S 499969 43
add 265 S 499989 56
add 266 B 500036 80
add 267 S 500026 22
add 268 S 499979 4
cancel 105
add 269 B 499993 62
add 270 S 499973 47
add 271 S 500023 43
cancel 235
add 272 S 499978 43
add 273 S 499999 92
cancel 193
add 274 B 499991 35
cancel 231
cancel 53
cancel 68
add 275 S 499993 8
add 276 B 499966 67
cancel 220
add 277 B 499990 72
add 278 B 500023 25
add 279 S 499963 64
add 280 S 499963 88
add 281 B 499977 50
cancel 152
add 282 B 499992 22
add 283 B 499950 46
add 284 B 499973 29
add 285 S 499969 72
add 286 B 499974 30
add 287 B 500005 44
add 288 S 500002 36
add 289 B 499982 93
add 290 S 500049 1
add 291 B 500036 82
add 292 S 499974 38
cancel 154
add 293 B 500027 48
cancel 91
add 294 B 500007 56
add 295 S 500041 6
cancel 67
cancel 132
add 296 S 499996 26
add 297 B 499955 45
add 298 B 499959 73
add 299 B 499973 33
add 300 S 500033 53
add 301 B 499954 87
add 302 B 500011 78
cancel 248
add 303 S 499999 56
add 304 S 499968 89
add 305 S 500032 44
cancel 115
cancel 143
add 306 S 500025 46
add 307 B 500024 45
add 308 S 499995 95
add 309 S 499952 43
add 310 S 499990 34
add 311 B 499967 1
add 312 S 499982 47
add 313 B 499998 39
add 314 B 500041 98
cancel 170
add 315 S 500007 28
cancel 96
cancel 242
add 316 S 499990 3
cancel 244
add 317 B 500036 5
add 318 B 500028 71
add 319 B 500047 14
add 320 S 500020 38
add 321 B 500045 20
add 322 S 499992 13
add 323 B 500040 82
add 324 S 499951 49
add 325 B 500033 27
add 326 S 499989 15
add 327 B 500038 17
add 328 B 499975 14
add 329 B 500022 44
add 330 S 500000 17
add 331 S 500041 43
add 332 S 500016 66
add 333 S 500015 22
cancel 240
add 334 S 500020 67
cancel 208
add 335 B 500019 32
add 336 B 499987 97
add 337 B 499973 42
add 338 B 499972 72
add 339 S 500009 40
add 340 S 500026 63
add 341 S 499981 81
add 342 S 499997 85
add 343 S 499988 95
add 344 B 499956 98
add 345 S 499988 98
add 346 B 499952 49
add 347 B 499975 65
cancel 13
cancel 293
add 348 S 500050 81
add 349 B 499965 75
add 350 B 499977 53
cancel 340
cancel 272
add 351 B 500011 64
add 352 B 500011 43
add 353 S 500043 32
add 354 B 500030 85
add 355 B 499972 91
add 356 B 499953 30
add 357 B 500030 1
add 358 B 499995 57
cancel 226
add 359 B 499981 25
cancel 222
add 360 B 499963 2
add 361 S 499951 25
add 362 S 500016 58
cancel 282
add 363 B 499990 11
add 364 S 500007 11
add 365 B 500017 95
